Workbook

Sheet DATA INPUT 
B2: Name of shop | C2: M/S.SHAS DESIGN AND PRINTING
B3: NAME OF BUILDING & LAND MARK /PLACE | C3: NEAR POST OFFICE, NILESHWAR
B4: BUILDING NO. | C4: W-III/1022
B5: GST NO.
B6: MONTHLY RENT OF SHOP | C6: 5500
B7: VILLAGE | C7: NILESHWAR
B8: MUNICIPALITY | C8: NILESHWAR
B9: POST OFFICE | C9: NILESHWAR
B10: TALUK | C10: HOSDURG
B11: BLOCK | C11: NILESHWAR
B12: DISTRICT | C12: KASARAGOD
B13: PIN CODE | C13: 671314
B14: AS PER ADHAR CARD
B15: GENDER | C15: MALE
B16: NAME OF PROPRIETOR | C16: SHAFEEK N N
B17: W/O S/O D/O | C17: S/o.
B18: Name of Father | C18: M MOIDEEN
B19: HOUSE NAME | C19: BAITHUL SHAMNA HOUSE
B20: VILLAGE | C20: KANHANGAD
B21: MUNICIPALITY | C21: NILESHWAR
B22: POST OFFICE | C22: OZHINJAVALAPPU
B23: TALUK | C23: HOSDURG
B24: BLOCK | C24: NILESHWAR
B25: DISTRICT | C25: KASARAGOD
B26: CONTACT NUMBER | C26: 9847599008
B27: PIN CODE | C27: 671314
B28: Date Of Birth | C28: 10/05/1988
B29: PAN No: | C29: EVOPS0533P
B30: ADHAAR CARD NO. | C30: 3616 3601 1234
B31: Line of activity | C31: SERVICE
B32: Status of the unit | C32: FRESH
B33: Qualification | C33: SSLC
B34: Experience (Yrs) in this field | C34: 12
B35: Proposed Business | C35: DIGITAL PRINTING
B36: Scheme of Loan | C36: MUDRA
B37: No. Of YEARS Loan Required | C37: 5
B38: NAMEOF BANK | C38: FEDERAL BANK
B39: BRANCH | C39: NILESHWAR
B41: IT SHOULBE SHOWN AFTER THE MACHINE & WC
B42: TOTAL PROJECT COST
...

Sheet INTRODUCTION 
B3: PROJECT –REPORT
E4: ON
B5: ='PROJECT REPORT '!H6 -> M/S.SHAS DESIGN AND PRINTING | H5: ='DATA INPUT '!C3 -> NEAR POST OFFICE, NILESHWAR
D6: PROMOTED BY : | H6: ='DATA INPUT '!C8 -> NILESHWAR
D7: ='PROJECT REPORT '!H17 -> Mr.SHAFEEK N N | G7: Cell No: | I7: ='DATA INPUT '!C26 -> 9847599008
D8: ='DATA INPUT '!C19 -> BAITHUL SHAMNA HOUSE
D9: ='DATA INPUT '!C21 -> NILESHWAR
D10: ='DATA INPUT '!C12 -> KASARAGOD
B41: FINANCE applied to
B43: ='DATA INPUT '!C38 -> FEDERAL BANK
B46: ='DATA INPUT '!$C$39 -> NILESHWAR
B59: v 1) INTRODUCTION
B62: v 2) PROJECT PARTICULARS
B65: v 3) SOURCE OF FINANCE
B68: v 4) COST OFMAINTAINENCE PER MONTH
B71: v 5) ANNUAL SALES TURNOVER AND REALISATION
B74: v 6) BREAK EVEN ANALYSIS
B77: v 7) DEBT SERVICE COVERAGE RATIO
B80: v 8) CASH FLOW
B83: v 9) PROJECTIONS OF PERFORMANCE & PROFITABILTY
B86: v 10) CONCLUSION
B97: 1.INTRODUCTION
B99: A well experienced Individual with sufficient background in his endeavor has proposed to set up a
B100: ='DATA INPUT '!C35 -> DIGITAL PRINTING
B101: unit under the name and style of
B102: =B5 -> M/S.SHAS DESIGN AND PRINTING
C103: ='DATA INPUT '!C3 -> NEAR POST OFFICE, NILESHWAR
C104: ='DATA INPUT '!C7 -> NILESHWAR
C105: =D10 -> KASARAGOD
C106: KERALA PIN - | E106: ='DATA INPUT '!C13 -> 671314
B109: Now-a-days, every activities of social and personal gathering increases the demand on printing
B110: Medias, such as flex banners, signage, advertisement posters, invitations cards etc… Such demands
B111: are met by a highly mechanized and computerized printing enterprise. A graphic printing enterprise
B112: provides each and every required printing medias to its users with a products and services ranging
B113: from low-end printing medias for single use to high quality printing medias
B119: PROMOTER
B121: The Proprietor and the sole owner of the unit is
B122: =D7 -> Mr.SHAFEEK N N
B123: ='DATA INPUT '!C17 -> S/o. | D123: ='PROJECT REPORT '!H18 -> M MOIDEEN
B124: Residing at | D124: ='DATA INPUT '!C19 -> BAITHUL SHAMNA HOUSE
...

Sheet PROJECT REPORT 
D3: 1.PROJECT HIGHLIGHTS
N4: YEAR OF LOAN
N5: 5
B6: Name Of Unit , Loaction & Address | H6: ='DATA INPUT '!C2 -> M/S.SHAS DESIGN AND PRINTING | N6: PENDING MONTHS IN THIS FINANCIAL YEAR
H7: ='DATA INPUT '!C3 -> NEAR POST OFFICE, NILESHWAR | N7: 8
B8: Building No. | H8: ='DATA INPUT '!C4 -> W-III/1022 | N8: 15 | O8: =MONTH(B847) -> 8 | P8: UPTO DEC WORK OUT
O9: =N8-O8 -> 7 | R9: =IF(O12="MALE",("his"),("her")) -> his
B10: Village | H10: ='DATA INPUT '!C8 -> NILESHWAR | N10: count from present month to next march
B11: Muicipalty/Panchayath | H11: ='DATA INPUT '!C8 -> NILESHWAR | O11: ='DATA INPUT '!C16 -> SHAFEEK N N
B12: Block | H12: ='DATA INPUT '!C11 -> NILESHWAR | O12: ='DATA INPUT '!C15 -> MALE | R12: =IF(O12="MALE",("He"),("She")) -> He
B13: Taluk | H13: ='DATA INPUT '!C10 -> HOSDURG
B14: District | H14: ='DATA INPUT '!C12 -> KASARAGOD | R14: IF FUNCTION KEY
B15: PIN | H15: ='DATA INPUT '!C13 -> 671314 | R15: 2
B16: Cell No: | H16: ='DATA INPUT '!C26 -> 9847599008 | N16: WORKING CAPITAL | P16: =IF(O21="PMEGP",(1),(3)) -> 3
B17: Chief Executive Name | H17: =IF(O12="MALE",("Mr."&O11),"Mrs."&O11) -> Mr.SHAFEEK N N | N17: Rqrd for Monyhly | O17: divided by 1 | S17: 3 MONTHS SALES REVENUE
B18: ='DATA INPUT '!B18 -> Name of Father | H18: ='DATA INPUT '!C18 -> M MOIDEEN | N18: Rqrd for Quarterly | O18: divided by 3
B19: Address | H19: ='DATA INPUT '!C19 -> BAITHUL SHAMNA HOUSE
H20: ='DATA INPUT '!C20 -> KANHANGAD | N20: MUDRA LOAN | O20: 0.75 | S20: IF (K11 >M13,"3MONTHS SALES REVENUE)
H21: ='DATA INPUT '!C11 -> NILESHWAR | O21: ='DATA INPUT '!C36 -> MUDRA | P21: 75 | S21: IF (K11 <M13,"MONTHLY SALES REVENUE)
H22: ='DATA INPUT '!C25 -> KASARAGOD | N22: PMEGP LOAN | O22: 0.95
H23: ='DATA INPUT '!C27 -> 671314
B24: Age, Date Of Birth | H24: ='DATA INPUT '!C28 -> 10/05/1988 | N24: NO. OF WORKERS | O24: NO. OF MACHINE WHICH IS HIGH ) | P24: =(J361/100000)+0.7 -> 8.51
B25: PAN No: | N25: Term loan amt divided by 1 lakh | P25: =ROUND(P24,0) -> 9
B26: ADHAAR CARD NO. | H26: ='DATA INPUT '!C30 -> 3616 3601 1234 | N26: without decimal , to nxt full digit
B27: Line of activity | H27: ='DATA INPUT '!C31 -> SERVICE
B28: Proposed Business | H28: ='DATA INPUT '!C35 -> DIGITAL PRINTING | N28: PERCENTAGE OF BANK LOAN INT. | P28: 10.5
B29: Status of the unit | H29: ='DATA INPUT '!C32 -> FRESH
B30: Qualification | H30: ='DATA INPUT '!C33 -> SSLC
B31: Yearsof Experience in this field | H31: ='DATA INPUT '!C34 -> 12 | N31: AUDIT FEE | R31: WC | S31: IF (M30 >M31,"1000)
N32: W.C UPTO 5 LAKH | O32: 500 | R32: =J307 -> 139830 | S32: IF (M30<M31,"500)
B33: Scheme of Loan | H33: OFOE | P33: =IF(R32>R33,"1000","500") -> 500 | R33: 500000
B34: Details of collateral security | H34: MACHINARY & STOCK | N34: W.C ABOVE 5 LAKH | O34: 1000
B35: Fixed Capital | H35: =L167 -> 781000 | O35: NOT LINKED
B36: working Capital | H36: =F308 -> 139830 | N36: DATE: FOR SUSHIL ONLY cuurent datein PR & + 5 days IN BANK APLLICATION
B37: Total Cost Of the Project | H37: =J365 -> 920830
B38: Means of Finance | N38: No. Of months loan required | P38: ='DATA INPUT '!C37*12 -> 60
B39: a) Own fund | H39: =F365 -> 285080
B40: b)Term Loan | H40: =H361 -> 585750 | N40: CHITTY | P40: =H41*5/100/2*12 -> 15000
B41: c)Working Capital loan | H41: =H363 -> 50000
B42: Total | H42: =SUM(H39:H41) -> 920830
...

Sheet T,P&L,BS
B2: =C72 -> M/S.SHAS DESIGN AND PRINTING
A3: TRADING AND PROFIT AND LOSS ACCOUNT FOR THE YEAR ENDED 31ST MARCH 2019
A5: PARTICULARS | C5: AMOUNT | D5: PARTICULARS | F5: AMOUNT
A7: To Opening stock | C7: 534520 | D7: By Sales | F7: 796061
A8: " Purchase | C8: 470500
D9: By Closing Stock | F9: =C78 -> 0
A10: " Gross profit C/d | C10: =F11-C7-C8-C9 -> -208959
A11: TOTAL | C11: =SUM(C7:C10) -> 796061 | D11: TOTAL | F11: =SUM(F6:F10) -> 796061
D13: " Gross profit B/d | F13: =C10 -> -208959
A14: " Salary& wages | C14: 248500
A15: " Electricity charges | C15: 10850
A16: " Repairs | C16: 3450
A17: " Transportation | C17: 8450
A18: " Telephone charges | C18: 5800 | G18: Profit to be come
A19: " Administrative expense | C19: 17500 | G19: 145550
A20: " Printing & stationery | C20: 2850
A21: " Miscellaneous expense | C21: 12350 | G21: =G19-C24 -> 706259
A22: " Depreciation | C22: =G46 -> 0
A23: " Rent | C23: 42000
A24: " Net Profit | C24: =F26-C14-C15-C16-C17-C18-C19-C20-C21-C22-C23 -> -560709
A26: TOTAL | C26: =SUM(C13:C25) -> -208959 | D26: TOTAL | F26: =SUM(F13:F25) -> -208959
D29: =B2 -> M/S.SHAS DESIGN AND PRINTING
D32: Proprietor
B37: =C72 -> M/S.SHAS DESIGN AND PRINTING
A38: BALANCE SHEET AS AT 31ST MARCH 2019
A39: LIABILITIES | B39: AMOUNT | C39: AMOUNT | D39: ASSETS | E39: AMOUNT | F39: AMOUNT
D40: FIXED ASSETS
A41: CAPITAL ACCOUNT | B41: 533897
A42: Add : Net profit | B42: =C24 -> -560709 | D42: =D115 -> MACHINERY & FITTINGS | E42: =I42 -> 0 | I42: =J42*111.1111/100 -> 0
B43: =SUM(B41:B42) -> -26812 | D43: Less depreciation | E43: =E42*10/100 -> 0 | F43: =E42-E43 -> 0
A44: Less : drawings | B44: 60000 | C44: =B43-B44 -> -86812 | D44: =D117 -> 0 | E44: =I44 -> 0 | I44: =J44*111.1111/100 -> 0
D45: Less depreciation | E45: =E44*10/100 -> 0 | F45: =E44-E45 -> 0 | G45: depreciation
D46: =D120 -> 0 | E46: =I46 -> 0 | G46: =E43+E45+E47 -> 0 | I46: =J46*111.1111/100 -> 0
D47: Less depreciation | E47: =E46*10/100 -> 0 | F47: =E46-E47 -> 0
G48: total asset
G49: =E42+E44+E46 -> 0
A51: SUNDRY CREDITORS | C51: 498305 | D51: CLOSING STOCK | F51: 745350
D53: SUNDRY DEBTORS | F53: 15580
G55: DIFFERENCE
D56: CASH AND BANK BALANCES | G56: =C58-F58 -> -362017
...

Sheet Depreciation Schedule
B16: ='T,P&L,BS'!B388 -> Mr.SHAFEEK N N | C16: ='T,P&L,BS'!C388 -> M/S.SHAS DESIGN AND PRINTING
A17: ='DATA INPUT '!C3 -> NEAR POST OFFICE, NILESHWAR
B18: DEPRECIATION SCHEDULE OF FIXED ASSET AS ON 31-03-2024
B20: PARTICULARS | C20: % | D20: Rs. Ps. | E20: Rs. Ps. | F20: Rs. Ps.
B22: ='PROJECT REPORT '!B84 -> 0 | D22: ='PROJECT REPORT '!H84 -> 0 | E22: =D22 -> 0
B23: Less: Depreciation Written off | C23: 10 | E23: =E22*10/100/12*'PROJECT REPORT '!O62 -> 0 | F23: =E22-E23 -> 0
B24: ='PROJECT REPORT '!B86 -> 0 | D24: ='PROJECT REPORT '!H86 -> 0 | E24: =SUM(D24:D24) -> 0
B25: Less: Depreciation Written off | C25: 10 | E25: =E24*10/100/12*'PROJECT REPORT '!O62 -> 0 | F25: =E24-E25 -> 0
B26: ='PROJECT REPORT '!B88 -> INVERTOR 3KVA | D26: ='PROJECT REPORT '!H88 -> 75000 | E26: =D26 -> 75000
B27: Less: Depreciation Written off | C27: 10 | E27: =E26*10/100/12*'PROJECT REPORT '!O62 -> 5000 | F27: =E26-E27 -> 70000
B28: ='PROJECT REPORT '!B89 -> GODREREJ A/C | D28: ='PROJECT REPORT '!H89 -> 35000 | E28: =D28 -> 35000
B29: Less: Depreciation Written off | C29: 10 | E29: =E28*10/100/12*'PROJECT REPORT '!O62 -> 2333.3333 | F29: =E28-E29 -> 32666.667
B30: ='PROJECT REPORT '!B90 -> LLOYD A/C | D30: ='PROJECT REPORT '!H90 -> 35000 | E30: =D30 -> 35000
B31: Less: Depreciation Written off | C31: 10 | E31: =E30*10/100/12*'PROJECT REPORT '!O62 -> 2333.3333 | F31: =E30-E31 -> 32666.667
B32: ='PROJECT REPORT '!B91 -> HALER A/C | D32: ='PROJECT REPORT '!H91 -> 40000 | E32: =D32 -> 40000
B33: Less: Depreciation Written off | C33: 10 | E33: =E32*10/100/12*'PROJECT REPORT '!O62 -> 2666.6667 | F33: =E32-E33 -> 37333.333
B34: ='PROJECT REPORT '!B92 -> COMPUTER CHAIR , TABLE Etc. | D34: ='PROJECT REPORT '!H92 -> 85000 | E34: =D34 -> 85000
B35: Less: Depreciation Written off | C35: 10 | E35: =E34*10/100/12*'PROJECT REPORT '!O62 -> 5666.6667 | F35: =E34-E35 -> 79333.333
B36: ='PROJECT REPORT '!B93 -> 0 | D36: ='PROJECT REPORT '!H93 -> 0 | E36: =SUM(D36:D36) -> 0
B37: Less: Depreciation Written off | C37: 10 | E37: =E36*10/100/12*'PROJECT REPORT '!O62 -> 0 | F37: =E36-E37 -> 0
B38: ='PROJECT REPORT '!B94 -> 0 | D38: ='PROJECT REPORT '!H94 -> 0 | E38: =D38 -> 0
B39: Less: Depreciation Written off | C39: 10 | D39: ='PROJECT REPORT '!H102 -> 0 | E39: =E38*10/100/12*'PROJECT REPORT '!O62 -> 0 | F39: =E38-E39 -> 0
B40: ='PROJECT REPORT '!B95 -> 0 | D40: ='PROJECT REPORT '!H95 -> 0 | E40: =D40 -> 0
B41: Less: Depreciation Written off | C41: 10 | E41: =E40*10/100/12*'PROJECT REPORT '!O62 -> 0 | F41: =E40-E41 -> 0
B42: ='PROJECT REPORT '!B96 -> 0 | D42: ='PROJECT REPORT '!H96 -> 0 | E42: =D42 -> 0
B43: Less: Depreciation Written off | C43: 10 | E43: =E42*10/100/12*'PROJECT REPORT '!O62 -> 0 | F43: =E42-E43 -> 0
B44: ='PROJECT REPORT '!B97 -> 0 | D44: ='PROJECT REPORT '!H97 -> 0 | E44: =D44 -> 0
B45: Less: Depreciation Written off | C45: 10 | E45: =E44*10/100/12*'PROJECT REPORT '!O62 -> 0 | F45: =E44-E45 -> 0
B46: ='PROJECT REPORT '!B98 -> 0 | D46: ='PROJECT REPORT '!H98 -> 0 | E46: =D46 -> 0
B47: Less: Depreciation Written off | C47: 10 | E47: =E46*10/100/12*'PROJECT REPORT '!O62 -> 0 | F47: =E46-E47 -> 0
B48: ='PROJECT REPORT '!B99 -> 0 | D48: ='PROJECT REPORT '!H99 -> 0 | E48: =D48 -> 0
B49: Less: Depreciation Written off | C49: 10 | E49: =E48*10/100/12*'PROJECT REPORT '!O62 -> 0 | F49: =E48-E49 -> 0
B50: ='PROJECT REPORT '!B100 -> 0 | D50: ='PROJECT REPORT '!H100 -> 0 | E50: =D50 -> 0
B51: Less: Depreciation Written off | C51: 10 | E51: =E50*10/100/12*'PROJECT REPORT '!O62 -> 0 | F51: =E50-E51 -> 0
B52: ='PROJECT REPORT '!B101 -> 0 | D52: ='PROJECT REPORT '!H101 -> 0 | E52: =D52 -> 0
B53: Less: Depreciation Written off | C53: 10 | E53: =E52*10/100/12*'PROJECT REPORT '!O62 -> 0 | F53: =E52-E53 -> 0
B54: ='PROJECT REPORT '!B102 -> 0 | D54: ='PROJECT REPORT '!H102 -> 0 | E54: =D54 -> 0
B55: Less: Depreciation Written off | C55: 10 | E55: =E54*10/100/12*'PROJECT REPORT '!O62 -> 0 | F55: =E54-E55 -> 0
B56: ='PROJECT REPORT '!B103 -> 0 | D56: ='PROJECT REPORT '!H103 -> 0 | E56: =D56 -> 0
B57: Less: Depreciation Written off | C57: 10 | E57: =E56*10/100/12*'PROJECT REPORT '!O62 -> 0 | F57: =E56-E57 -> 0
...

Sheet MUDRA 
A8: LOAN APPLICATION FORM MSME LOAN UPTO 50 LAKH
B9: (To be submitted along with documents as per the checklist)
A11: A. For office Use:
A13: Enterprise Name | C13: Application Sl. No. | E13: Name of the Branch | G13: Category
A14: ='PROJECT REPORT '!H6 -> M/S.SHAS DESIGN AND PRINTING | E14: ='PROJECT REPORT '!H53 -> NILESHWAR | G14: Shishu/Kishor/Tarun
A16: B.Business Information:
A18: Name of Enterprise | C18: =A14 -> M/S.SHAS DESIGN AND PRINTING
B20: Constitution I √ | C20: Proprietary | D20: Partnership | E20: Pvt. Ltd. | F20: Ltd. Company | G20: Any Others (specify)
A21: Current
A22: Business
A23: Adress | C23: State | D23: KERALA | E23: PIN Code | G23: ='PROJECT REPORT '!H15 -> 671314
C24: Business Premises | E24: √ | F24: Rented | G24: Owned | H24: Leased
A26: Adress Of the | C26: ='PROJECT REPORT '!H8 -> W-III/1022 | D26: ='PROJECT REPORT '!H7 -> NEAR POST OFFICE, NILESHWAR
A27: Factory/Shop/ | C27: ='PROJECT REPORT '!H11 -> NILESHWAR
A28: Business | C28: ='PROJECT REPORT '!H14 -> KASARAGOD
A29: Taluk | C29: ='PROJECT REPORT '!H13 -> HOSDURG | F29: District | G29: ='PROJECT REPORT '!H14 -> KASARAGOD
A30: Telephone No. | F30: Mobile No. | G30: ='PROJECT REPORT '!H16 -> 9847599008
A31: Email ID
A32: Business | C32: Existing | E32: ='PROJECT REPORT '!H28 -> DIGITAL PRINTING
A33: Activity | C33: Proposed
A34: Date of Commencement(DD/MM/YYYY
A35: Whether the Unit is Registered | D35: √ | E35: Yes | G35: No
A36: If Registered (Please mention:Registration
A37: no. And the Act under which registered )
A38: Registered office Address | D38: SAME S ABOVE
A40: Social Category | C40: √ | D40: SC | E40: ST | F40: OBC | G40: Minority | H40: General
A41: If MinorityCommunity √ | C41: Budhist | D41: Muslims | E41: Christians | F41: Sikhs | G41: Jains | H41: Zoroastrians
A43: C.Background Information of Proprietor/ Partners/ Directors:
A45: S.No | B45: Name | C45: Date of Birth | D45: Sex | E45: Residential Address with Mobile No. | G45: Academic qualification | H45: Experience in the line of activity(Years)
A46: 1. | B46: ='PROJECT REPORT '!H17 -> Mr.SHAFEEK N N | C46: ='PROJECT REPORT '!H24 -> 10/05/1988 | D46: ='DATA INPUT '!C15 -> MALE | E46: ='PROJECT REPORT '!H19 -> BAITHUL SHAMNA HOUSE
E47: ='PROJECT REPORT '!H20 -> KANHANGAD | G47: ='PROJECT REPORT '!H30 -> SSLC | H47: ='PROJECT REPORT '!H31 -> 12
E48: ='PROJECT REPORT '!H21 -> NILESHWAR | H48: 6 YEARS
E49: ='PROJECT REPORT '!H16 -> 9847599008
A50: 2.
A53: S.No | B53: Id proof no. | C53: Id proof | D53: Address proof | E53: PAN Card/DIN No. | G53: Relationship with the officials/ Director of the bank if any
A54: 1. | B54: ='PROJECT REPORT '!H26 -> 3616 3601 1234 | C54: ='PROJECT REPORT '!B26 -> ADHAAR CARD NO. | D54: ='PROJECT REPORT '!B25 -> PAN No: | E54: ='PROJECT REPORT '!H25 -> 0 | G54: NA
A56: 2.
A61: D. Names of Associate Concerns and Nature of Association
A62: Names of Associate Concern | C62: Address of Associate Concern | D62: Presently Banking with | E62: Nature of Association Concern | F62: Extent of Interest as a Prop./Partner/ Director or Just Investor in Associate Concern
A63: NA | C63: NA | D63: NA | E63: NA | F63: NA
...

Sheet Sheet1
A2: LA BELLE BOUTIQUE
A3: CITY CENTER, OPP ST. MARYS GHS SCHOOL PAYYANUR.
A4: Mob: 9895305797
A5: 32BEIPT 9737A1ZE QOUTATION
A6: To
B7: Mr. Rameshan | C7: No. : | D7: 42
B8: ROOTS BEAUTY SPA | C8: Date : | D8: 44539
B9: WOODYZ TOWER , KANHANGAD
A12: S.No. | B12: DESCRIPTION | C12: RATE | D12: QTY | E12: AMOUNT
A13: 1 | B13: RAAGA PB SPA 4HEAD NOURISHMENT CREAM BATH 750 ML | C13: 417.7126 | D13: 35 | E13: 14619.941
A14: 2 | B14: RAAGA PB SPA 4HEAD NOURISHMENT CREAM BATH 750 ML | C14: 417.7126 | D14: 35 | E14: 14619.941
A15: 3 | B15: RAAGA ECO PAK WITH PILY SKIN 200M | C15: 223.3054 | D15: 75 | E15: 16747.905
A16: 4 | B16: RAAGA STEMCELLS PLATINUM FACIAL KIT 61G | C16: 246.9522 | D16: 60 | E16: 14817.132
A17: 5 | B17: RAAGA PROF STEMCELLS FAIRNESS KIT 61G | C17: 218.0478 | D17: 75 | E17: 16353.585
A18: 6 | B18: RAGA PROF STEMCELLS ANTICANE FACIAL KIT 61G | C18: 225.9342 | D18: 60 | E18: 13556.052
A19: 7 | B19: RAAGA PEDI MENI ALOVERA 63GM | C19: 144.491 | D19: 75 | E19: 10836.825
A20: 8 | B20: RAAGA LS WAX ALOVERA 800ML | C20: 520.1676 | D20: 100 | E20: 52016.76
A21: 9 | B21: RAAGA PB CLR PROTECT SHAMPOO &CONDITIONER 1000ML | C21: 1024.5748 | D21: 25 | E21: 25614.37
A22: 10 | B22: SCHWARZKOPF GLATT STRAIGHTENER AND NEUTRALIZING BALM | C22: 1011.4432 | D22: 22.5 | E22: 22757.472
A23: 11 | B23: SCHWARZKOPF SCALP GENESIS PURIFYING SHAMPOO | C23: 499.1496 | D23: 28 | E23: 13976.189
A24: 12 | B24: SHAHNAZ GOLD SKIN RADIANCE KIT | C24: 530.6766 | D24: 15 | E24: 7960.149
... A45: 33 | B45: CALEO DIAMOND SPA FACIAL KIT 280 ML | C45: 629.982 | D45: 15 | E45: 9449.73
D46: =SUM(D13:D45) -> 1138.5 | E46: =SUM(E13:E45) -> 646412.83
B47: . | C47: GST @18% | E47: =E46*18/100 -> 116354.31
C48: Grand Total | E48: =SUM(E46:E47) -> 762767.14
A49: E&OE
A50: (Rupees Seven Lakh Sixty Two Thousand Sevenhundred and Sixty Seven Only)
C53: Authorised Signatory
